[2023-09-03 21:47:40,667] {taskinstance.py:903} INFO - Dependencies all met for <TaskInstance: my_dag_name.CWLJobDispatcher 2023-09-03T21:47:21.570903+00:00 [None]>
[2023-09-03 21:47:40,678] {taskinstance.py:903} INFO - Dependencies all met for <TaskInstance: my_dag_name.CWLJobDispatcher 2023-09-03T21:47:21.570903+00:00 [None]>
[2023-09-03 21:47:40,679] {taskinstance.py:1095} INFO - 
--------------------------------------------------------------------------------
[2023-09-03 21:47:40,679] {taskinstance.py:1096} INFO - Starting attempt 1 of 1
[2023-09-03 21:47:40,680] {taskinstance.py:1097} INFO - 
--------------------------------------------------------------------------------
[2023-09-03 21:47:40,696] {taskinstance.py:1115} INFO - Executing <Task(CWLJobDispatcher): CWLJobDispatcher> on 2023-09-03T21:47:21.570903+00:00
[2023-09-03 21:47:40,700] {standard_task_runner.py:52} INFO - Started process 117 to run task
[2023-09-03 21:47:40,706] {standard_task_runner.py:76} INFO - Running: ['***', 'tasks', 'run', 'my_dag_name', 'CWLJobDispatcher', '2023-09-03T21:47:21.570903+00:00', '--job-id', '8', '--pool', 'default_pool', '--raw', '--subdir', 'DAGS_FOLDER/my_dag.py', '--cfg-path', '/tmp/tmple2m1i29', '--error-file', '/tmp/tmpuuvl6yfz']
[2023-09-03 21:47:40,707] {standard_task_runner.py:77} INFO - Job 8: Subtask CWLJobDispatcher
[2023-09-03 21:47:40,753] {logging_mixin.py:109} INFO - Running <TaskInstance: my_dag_name.CWLJobDispatcher 2023-09-03T21:47:21.570903+00:00 [running]> on host 67ec268b9854
[2023-09-03 21:47:40,809] {taskinstance.py:1252} INFO - Exporting the following env vars:
AIRFLOW_CTX_DAG_OWNER=***
AIRFLOW_CTX_DAG_ID=my_dag_name
AIRFLOW_CTX_TASK_ID=CWLJobDispatcher
AIRFLOW_CTX_EXECUTION_DATE=2023-09-03T21:47:21.570903+00:00
AIRFLOW_CTX_DAG_RUN_ID=manual__2023-09-03T21:47:21.570903+00:00
[2023-09-03 21:47:40,821] {taskinstance.py:1463} ERROR - Task failed with exception
Traceback (most recent call last):
  File "/home/airflow/.local/lib/python3.8/site-packages/airflow/models/taskinstance.py", line 1165, in _run_raw_task
    self._prepare_and_execute_task_with_callbacks(context, task)
  File "/home/airflow/.local/lib/python3.8/site-packages/airflow/models/taskinstance.py", line 1283, in _prepare_and_execute_task_with_callbacks
    result = self._execute_task(context, task_copy)
  File "/home/airflow/.local/lib/python3.8/site-packages/airflow/models/taskinstance.py", line 1313, in _execute_task
    result = task_copy.execute(context=context)
  File "/home/airflow/.local/lib/python3.8/site-packages/cwl_airflow/extensions/operators/cwljobdispatcher.py", line 55, in execute
    job=context["dag_run"].conf["job"],
KeyError: 'job'
[2023-09-03 21:47:40,823] {taskinstance.py:1506} INFO - Marking task as FAILED. dag_id=my_dag_name, task_id=CWLJobDispatcher, execution_date=20230903T214721, start_date=20230903T214740, end_date=20230903T214740
[2023-09-03 21:47:40,878] {local_task_job.py:151} INFO - Task exited with return code 1
[2023-09-03 21:47:40,903] {taskinstance.py:1342} ERROR - Error when executing on_failure_callback
Traceback (most recent call last):
  File "/home/airflow/.local/lib/python3.8/site-packages/airflow/models/taskinstance.py", line 1340, in _run_finished_callback
    task.on_failure_callback(context)
  File "/home/airflow/.local/lib/python3.8/site-packages/cwl_airflow/utilities/report.py", line 338, in task_on_failure
    append_cwl_log(context)
  File "/home/airflow/.local/lib/python3.8/site-packages/cwl_airflow/utilities/report.py", line 59, in append_cwl_log
    cwl_logs, _ = cwl_log_handler.read(ti)
AttributeError: 'NoneType' object has no attribute 'read'
[2023-09-03 21:47:40,920] {local_task_job.py:261} INFO - 0 downstream tasks scheduled from follow-on schedule check
